Workbook
Name DistributorList: Summary!$AA$1:$AA$8
Name VarianceThreshold: Summary!$C$5

Sheet Summary
A1: Distributor variance | AA1: D01
AA2: D02
A3: Distributor | C3: D01 | AA3: D03
A4: Change the yellow cell to switch distributor. Totals below use SUMIFS. | AA4: D04
A5: Flag threshold | C5: 0.05 | AA5: D05
AA6: D06
B7: Internal liters | C7: =SUMIFS(WeeklyByDistributor[internal_liters],WeeklyByDistributor[distributor_id],$C$3) -> 0 | AA7: D07
B8: Feed liters | C8: =SUMIFS(WeeklyByDistributor[feed_liters],WeeklyByDistributor[distributor_id],$C$3) -> 0 | AA8: D08
B9: Variance liters | C9: =C8-C7 -> 0
B10: Variance percent | C10: =IF(C7=0,"",C9/C7) -> 0
A12: All distributors
A13: Distributor | B13: Internal liters | C13: Feed liters | D13: Variance liters | E13: Variance percent
A14: D01 | B14: =SUMIFS(WeeklyByDistributor[internal_liters],WeeklyByDistributor[distributor_id],A14) -> 0 | C14: =SUMIFS(WeeklyByDistributor[feed_liters],WeeklyByDistributor[distributor_id],A14) -> 0 | D14: =C14-B14 -> 0 | E14: =IF(B14=0,"",D14/B14) -> 0
A15: D02 | B15: =SUMIFS(WeeklyByDistributor[internal_liters],WeeklyByDistributor[distributor_id],A15) -> 0 | C15: =SUMIFS(WeeklyByDistributor[feed_liters],WeeklyByDistributor[distributor_id],A15) -> 0 | D15: =C15-B15 -> 0 | E15: =IF(B15=0,"",D15/B15) -> 0
A16: D03 | B16: =SUMIFS(WeeklyByDistributor[internal_liters],WeeklyByDistributor[distributor_id],A16) -> 0 | C16: =SUMIFS(WeeklyByDistributor[feed_liters],WeeklyByDistributor[distributor_id],A16) -> 0 | D16: =C16-B16 -> 0 | E16: =IF(B16=0,"",D16/B16) -> 0
A17: D04 | B17: =SUMIFS(WeeklyByDistributor[internal_liters],WeeklyByDistributor[distributor_id],A17) -> 0 | C17: =SUMIFS(WeeklyByDistributor[feed_liters],WeeklyByDistributor[distributor_id],A17) -> 0 | D17: =C17-B17 -> 0 | E17: =IF(B17=0,"",D17/B17) -> 0
A18: D05 | B18: =SUMIFS(WeeklyByDistributor[internal_liters],WeeklyByDistributor[distributor_id],A18) -> 0 | C18: =SUMIFS(WeeklyByDistributor[feed_liters],WeeklyByDistributor[distributor_id],A18) -> 0 | D18: =C18-B18 -> 0 | E18: =IF(B18=0,"",D18/B18) -> 0
A19: D06 | B19: =SUMIFS(WeeklyByDistributor[internal_liters],WeeklyByDistributor[distributor_id],A19) -> 0 | C19: =SUMIFS(WeeklyByDistributor[feed_liters],WeeklyByDistributor[distributor_id],A19) -> 0 | D19: =C19-B19 -> 0 | E19: =IF(B19=0,"",D19/B19) -> 0
A20: D07 | B20: =SUMIFS(WeeklyByDistributor[internal_liters],WeeklyByDistributor[distributor_id],A20) -> 0 | C20: =SUMIFS(WeeklyByDistributor[feed_liters],WeeklyByDistributor[distributor_id],A20) -> 0 | D20: =C20-B20 -> 0 | E20: =IF(B20=0,"",D20/B20) -> 0
A21: D08 | B21: =SUMIFS(WeeklyByDistributor[internal_liters],WeeklyByDistributor[distributor_id],A21) -> 0 | C21: =SUMIFS(WeeklyByDistributor[feed_liters],WeeklyByDistributor[distributor_id],A21) -> 0 | D21: =C21-B21 -> 0 | E21: =IF(B21=0,"",D21/B21) -> 0

Sheet Weekly_Compare
A1: distributor_id | B1: week | C1: account_id | D1: sku_id | E1: sku_name | F1: account_name | G1: city | H1: internal_liters | I1: feed_liters | J1: variance_liters | K1: variance_pct | L1: compare_flag | M1: root_cause
A2: D01 | B2: 2023-01-02 | C2: 2633 | D2: 15888 | E2: {=_xlfn.XLOOKUP(D2,SKU_Master!A:A,SKU_Master!B:B,"Not on master")} -> 0 | F2: {=_xlfn.XLOOKUP(C2,Account_Master!A:A,Account_Master!B:B,"Not on master")} -> 0 | G2: {=_xlfn.XLOOKUP(C2,Account_Master!A:A,Account_Master!C:C,"Not on master")} -> 0 | H2: 18 | I2: 18 | J2: =I2-H2 -> 0 | K2: =IF(H2=0,"",J2/H2) -> 0 | L2: =IF(OR(AND(H2=0,ABS(J2)>=0.01),AND(H2<>0,ABS(K2)>VarianceThreshold)),"Review","OK") -> 0
A3: D01 | B3: 2023-01-02 | C3: 2620 | D3: 17566 | E3: {=_xlfn.XLOOKUP(D3,SKU_Master!A:A,SKU_Master!B:B,"Not on master")} -> 0 | F3: {=_xlfn.XLOOKUP(C3,Account_Master!A:A,Account_Master!B:B,"Not on master")} -> 0 | G3: {=_xlfn.XLOOKUP(C3,Account_Master!A:A,Account_Master!C:C,"Not on master")} -> 0 | H3: 0.75 | I3: 0.75 | J3: =I3-H3 -> 0 | K3: =IF(H3=0,"",J3/H3) -> 0 | L3: =IF(OR(AND(H3=0,ABS(J3)>=0.01),AND(H3<>0,ABS(K3)>VarianceThreshold)),"Review","OK") -> 0
A4: D01 | B4: 2023-01-02 | C4: 2633 | D4: 38169 | E4: {=_xlfn.XLOOKUP(D4,SKU_Master!A:A,SKU_Master!B:B,"Not on master")} -> 0 | F4: {=_xlfn.XLOOKUP(C4,Account_Master!A:A,Account_Master!B:B,"Not on master")} -> 0 | G4: {=_xlfn.XLOOKUP(C4,Account_Master!A:A,Account_Master!C:C,"Not on master")} -> 0 | H4: 28.5 | I4: 28.5 | J4: =I4-H4 -> 0 | K4: =IF(H4=0,"",J4/H4) -> 0 | L4: =IF(OR(AND(H4=0,ABS(J4)>=0.01),AND(H4<>0,ABS(K4)>VarianceThreshold)),"Review","OK") -> 0
A5: D01 | B5: 2023-01-02 | C5: 4877 | D5: 6076 | E5: {=_xlfn.XLOOKUP(D5,SKU_Master!A:A,SKU_Master!B:B,"Not on master")} -> 0 | F5: {=_xlfn.XLOOKUP(C5,Account_Master!A:A,Account_Master!B:B,"Not on master")} -> 0 | G5: {=_xlfn.XLOOKUP(C5,Account_Master!A:A,Account_Master!C:C,"Not on master")} -> 0 | H5: 1.5 | I5: 1.5 | J5: =I5-H5 -> 0 | K5: =IF(H5=0,"",J5/H5) -> 0 | L5: =IF(OR(AND(H5=0,ABS(J5)>=0.01),AND(H5<>0,ABS(K5)>VarianceThreshold)),"Review","OK") -> 0
A6: D01 | B6: 2023-01-02 | C6: 2633 | D6: 64736 | E6: {=_xlfn.XLOOKUP(D6,SKU_Master!A:A,SKU_Master!B:B,"Not on master")} -> 0 | F6: {=_xlfn.XLOOKUP(C6,Account_Master!A:A,Account_Master!B:B,"Not on master")} -> 0 | G6: {=_xlfn.XLOOKUP(C6,Account_Master!A:A,Account_Master!C:C,"Not on master")} -> 0 | H6: 30 | I6: 30 | J6: =I6-H6 -> 0 | K6: =IF(H6=0,"",J6/H6) -> 0 | L6: =IF(OR(AND(H6=0,ABS(J6)>=0.01),AND(H6<>0,ABS(K6)>VarianceThreshold)),"Review","OK") -> 0
A7: D01 | B7: 2023-01-02 | C7: 2633 | D7: 68036 | E7: {=_xlfn.XLOOKUP(D7,SKU_Master!A:A,SKU_Master!B:B,"Not on master")} -> 0 | F7: {=_xlfn.XLOOKUP(C7,Account_Master!A:A,Account_Master!B:B,"Not on master")} -> 0 | G7: {=_xlfn.XLOOKUP(C7,Account_Master!A:A,Account_Master!C:C,"Not on master")} -> 0 | H7: 210 | I7: 219 | J7: =I7-H7 -> 0 | K7: =IF(H7=0,"",J7/H7) -> 0 | L7: =IF(OR(AND(H7=0,ABS(J7)>=0.01),AND(H7<>0,ABS(K7)>VarianceThreshold)),"Review","OK") -> 0
A8: D01 | B8: 2023-01-02 | C8: 5443 | D8: 86669 | E8: {=_xlfn.XLOOKUP(D8,SKU_Master!A:A,SKU_Master!B:B,"Not on master")} -> 0 | F8: {=_xlfn.XLOOKUP(C8,Account_Master!A:A,Account_Master!B:B,"Not on master")} -> 0 | G8: {=_xlfn.XLOOKUP(C8,Account_Master!A:A,Account_Master!C:C,"Not on master")} -> 0 | H8: 15.36 | I8: 15.36 | J8: =I8-H8 -> 0 | K8: =IF(H8=0,"",J8/H8) -> 0 | L8: =IF(OR(AND(H8=0,ABS(J8)>=0.01),AND(H8<>0,ABS(K8)>VarianceThreshold)),"Review","OK") -> 0
A9: D01 | B9: 2023-01-02 | C9: 2548 | D9: 87385 | E9: {=_xlfn.XLOOKUP(D9,SKU_Master!A:A,SKU_Master!B:B,"Not on master")} -> 0 | F9: {=_xlfn.XLOOKUP(C9,Account_Master!A:A,Account_Master!B:B,"Not on master")} -> 0 | G9: {=_xlfn.XLOOKUP(C9,Account_Master!A:A,Account_Master!C:C,"Not on master")} -> 0 | H9: 6 | I9: 6 | J9: =I9-H9 -> 0 | K9: =IF(H9=0,"",J9/H9) -> 0 | L9: =IF(OR(AND(H9=0,ABS(J9)>=0.01),AND(H9<>0,ABS(K9)>VarianceThreshold)),"Review","OK") -> 0
A10: D01 | B10: 2023-01-02 | C10: 2666 | D10: 89781 | E10: {=_xlfn.XLOOKUP(D10,SKU_Master!A:A,SKU_Master!B:B,"Not on master")} -> 0 | F10: {=_xlfn.XLOOKUP(C10,Account_Master!A:A,Account_Master!B:B,"Not on master")} -> 0 | G10: {=_xlfn.XLOOKUP(C10,Account_Master!A:A,Account_Master!C:C,"Not on master")} -> 0 | H10: 0.15 | I10: 0.15 | J10: =I10-H10 -> 0 | K10: =IF(H10=0,"",J10/H10) -> 0 | L10: =IF(OR(AND(H10=0,ABS(J10)>=0.01),AND(H10<>0,ABS(K10)>VarianceThreshold)),"Review","OK") -> 0
A11: D01 | B11: 2023-01-09 | C11: 5651 | D11: 12407 | E11: {=_xlfn.XLOOKUP(D11,SKU_Master!A:A,SKU_Master!B:B,"Not on master")} -> 0 | F11: {=_xlfn.XLOOKUP(C11,Account_Master!A:A,Account_Master!B:B,"Not on master")} -> 0 | G11: {=_xlfn.XLOOKUP(C11,Account_Master!A:A,Account_Master!C:C,"Not on master")} -> 0 | H11: 3 | I11: 3 | J11: =I11-H11 -> 0 | K11: =IF(H11=0,"",J11/H11) -> 0 | L11: =IF(OR(AND(H11=0,ABS(J11)>=0.01),AND(H11<>0,ABS(K11)>VarianceThreshold)),"Review","OK") -> 0
A12: D01 | B12: 2023-01-09 | C12: 2626 | D12: 26824 | E12: {=_xlfn.XLOOKUP(D12,SKU_Master!A:A,SKU_Master!B:B,"Not on master")} -> 0 | F12: {=_xlfn.XLOOKUP(C12,Account_Master!A:A,Account_Master!B:B,"Not on master")} -> 0 | G12: {=_xlfn.XLOOKUP(C12,Account_Master!A:A,Account_Master!C:C,"Not on master")} -> 0 | H12: 38.23 | I12: 38.23 | J12: =I12-H12 -> 0 | K12: =IF(H12=0,"",J12/H12) -> 0 | L12: =IF(OR(AND(H12=0,ABS(J12)>=0.01),AND(H12<>0,ABS(K12)>VarianceThreshold)),"Review","OK") -> 0
A13: D01 | B13: 2023-01-09 | C13: 5145 | D13: 27781 | E13: {=_xlfn.XLOOKUP(D13,SKU_Master!A:A,SKU_Master!B:B,"Not on master")} -> 0 | F13: {=_xlfn.XLOOKUP(C13,Account_Master!A:A,Account_Master!B:B,"Not on master")} -> 0 | G13: {=_xlfn.XLOOKUP(C13,Account_Master!A:A,Account_Master!C:C,"Not on master")} -> 0 | H13: 4.8 | I13: 4.8 | J13: =I13-H13 -> 0 | K13: =IF(H13=0,"",J13/H13) -> 0 | L13: =IF(OR(AND(H13=0,ABS(J13)>=0.01),AND(H13<>0,ABS(K13)>VarianceThreshold)),"Review","OK") -> 0
... A303: D01 | B303: 2023-11-20 | C303: 010227 | D303: 43334 | E303: {=_xlfn.XLOOKUP(D303,SKU_Master!A:A,SKU_Master!B:B,"Not on master")} -> 0 | F303: {=_xlfn.XLOOKUP(C303,Account_Master!A:A,Account_Master!B:B,"Not on master")} -> 0 | G303: {=_xlfn.XLOOKUP(C303,Account_Master!A:A,Account_Master!C:C,"Not on master")} -> 0 | H303: 141.73 | I303: 141.73 | J303: =I303-H303 -> 0 | K303: =IF(H303=0,"",J303/H303) -> 0 | L303: =IF(OR(AND(H303=0,ABS(J303)>=0.01),AND(H303<>0,ABS(K303)>VarianceThreshold)),"Review","OK") -> 0
A304: D01 | B304: 2023-11-20 | C304: 6209 | D304: 5753 | E304: {=_xlfn.XLOOKUP(D304,SKU_Master!A:A,SKU_Master!B:B,"Not on master")} -> 0 | F304: {=_xlfn.XLOOKUP(C304,Account_Master!A:A,Account_Master!B:B,"Not on master")} -> 0 | G304: {=_xlfn.XLOOKUP(C304,Account_Master!A:A,Account_Master!C:C,"Not on master")} -> 0 | H304: 0 | I304: 0.05 | J304: =I304-H304 -> 0 | K304: =IF(H304=0,"",J304/H304) -> 0 | L304: =IF(OR(AND(H304=0,ABS(J304)>=0.01),AND(H304<>0,ABS(K304)>VarianceThreshold)),"Review","OK") -> 0 | M304: Unknown
A305: D01 | B305: 2023-11-20 | C305: 4084 | D305: 58874 | E305: {=_xlfn.XLOOKUP(D305,SKU_Master!A:A,SKU_Master!B:B,"Not on master")} -> 0 | F305: {=_xlfn.XLOOKUP(C305,Account_Master!A:A,Account_Master!B:B,"Not on master")} -> 0 | G305: {=_xlfn.XLOOKUP(C305,Account_Master!A:A,Account_Master!C:C,"Not on master")} -> 0 | H305: 10.5 | I305: 10.5 | J305: =I305-H305 -> 0 | K305: =IF(H305=0,"",J305/H305) -> 0 | L305: =IF(OR(AND(H305=0,ABS(J305)>=0.01),AND(H305<>0,ABS(K305)>VarianceThreshold)),"Review","OK") -> 0
A306: D01 | B306: 2023-11-20 | C306: 2633 | D306: 65257 | E306: {=_xlfn.XLOOKUP(D306,SKU_Master!A:A,SKU_Master!B:B,"Not on master")} -> 0 | F306: {=_xlfn.XLOOKUP(C306,Account_Master!A:A,Account_Master!B:B,"Not on master")} -> 0 | G306: {=_xlfn.XLOOKUP(C306,Account_Master!A:A,Account_Master!C:C,"Not on master")} -> 0 | H306: 256 | I306: 256 | J306: =I306-H306 -> 0 | K306: =IF(H306=0,"",J306/H306) -> 0 | L306: =IF(OR(AND(H306=0,ABS(J306)>=0.01),AND(H306<>0,ABS(K306)>VarianceThreshold)),"Review","OK") -> 0
A307: D01 | B307: 2023-11-20 | C307: 2561 | D307: 73588 | E307: {=_xlfn.XLOOKUP(D307,SKU_Master!A:A,SKU_Master!B:B,"Not on master")} -> 0 | F307: {=_xlfn.XLOOKUP(C307,Account_Master!A:A,Account_Master!B:B,"Not on master")} -> 0 | G307: {=_xlfn.XLOOKUP(C307,Account_Master!A:A,Account_Master!C:C,"Not on master")} -> 0 | H307: 16.5 | I307: 16.5 | J307: =I307-H307 -> 0 | K307: =IF(H307=0,"",J307/H307) -> 0 | L307: =IF(OR(AND(H307=0,ABS(J307)>=0.01),AND(H307<>0,ABS(K307)>VarianceThreshold)),"Review","OK") -> 0
A308: D01 | B308: 2023-11-20 | C308: 2633 | D308: 75264 | E308: {=_xlfn.XLOOKUP(D308,SKU_Master!A:A,SKU_Master!B:B,"Not on master")} -> 0 | F308: {=_xlfn.XLOOKUP(C308,Account_Master!A:A,Account_Master!B:B,"Not on master")} -> 0 | G308: {=_xlfn.XLOOKUP(C308,Account_Master!A:A,Account_Master!C:C,"Not on master")} -> 0 | H308: 9 | I308: 9 | J308: =I308-H308 -> 0 | K308: =IF(H308=0,"",J308/H308) -> 0 | L308: =IF(OR(AND(H308=0,ABS(J308)>=0.01),AND(H308<>0,ABS(K308)>VarianceThreshold)),"Review","OK") -> 0
A309: D01 | B309: 2023-11-20 | C309: 4971 | D309: 80362 | E309: {=_xlfn.XLOOKUP(D309,SKU_Master!A:A,SKU_Master!B:B,"Not on master")} -> 0 | F309: {=_xlfn.XLOOKUP(C309,Account_Master!A:A,Account_Master!B:B,"Not on master")} -> 0 | G309: {=_xlfn.XLOOKUP(C309,Account_Master!A:A,Account_Master!C:C,"Not on master")} -> 0 | H309: 4.5 | I309: 4.5 | J309: =I309-H309 -> 0 | K309: =IF(H309=0,"",J309/H309) -> 0 | L309: =IF(OR(AND(H309=0,ABS(J309)>=0.01),AND(H309<>0,ABS(K309)>VarianceThreshold)),"Review","OK") -> 0
A310: D01 | B310: 2023-11-27 | C310: 6214 | D310: 101815 | E310: {=_xlfn.XLOOKUP(D310,SKU_Master!A:A,SKU_Master!B:B,"Not on master")} -> 0 | F310: {=_xlfn.XLOOKUP(C310,Account_Master!A:A,Account_Master!B:B,"Not on master")} -> 0 | G310: {=_xlfn.XLOOKUP(C310,Account_Master!A:A,Account_Master!C:C,"Not on master")} -> 0 | H310: 4.5 | I310: 4.5 | J310: =I310-H310 -> 0 | K310: =IF(H310=0,"",J310/H310) -> 0 | L310: =IF(OR(AND(H310=0,ABS(J310)>=0.01),AND(H310<>0,ABS(K310)>VarianceThreshold)),"Review","OK") -> 0
A311: D01 | B311: 2023-11-27 | C311: 2548 | D311: 10836 | E311: {=_xlfn.XLOOKUP(D311,SKU_Master!A:A,SKU_Master!B:B,"Not on master")} -> 0 | F311: {=_xlfn.XLOOKUP(C311,Account_Master!A:A,Account_Master!B:B,"Not on master")} -> 0 | G311: {=_xlfn.XLOOKUP(C311,Account_Master!A:A,Account_Master!C:C,"Not on master")} -> 0 | H311: 31.5 | I311: 31.5 | J311: =I311-H311 -> 0 | K311: =IF(H311=0,"",J311/H311) -> 0 | L311: =IF(OR(AND(H311=0,ABS(J311)>=0.01),AND(H311<>0,ABS(K311)>VarianceThreshold)),"Review","OK") -> 0
A312: D01 | B312: 2023-11-27 | C312: 4273 | D312: 22784 | E312: {=_xlfn.XLOOKUP(D312,SKU_Master!A:A,SKU_Master!B:B,"Not on master")} -> 0 | F312: {=_xlfn.XLOOKUP(C312,Account_Master!A:A,Account_Master!B:B,"Not on master")} -> 0 | G312: {=_xlfn.XLOOKUP(C312,Account_Master!A:A,Account_Master!C:C,"Not on master")} -> 0 | H312: 29.25 | I312: 29.25 | J312: =I312-H312 -> 0 | K312: =IF(H312=0,"",J312/H312) -> 0 | L312: =IF(OR(AND(H312=0,ABS(J312)>=0.01),AND(H312<>0,ABS(K312)>VarianceThreshold)),"Review","OK") -> 0
A313: D01 | B313: 2023-11-27 | C313: 2548 | D313: 27604 | E313: {=_xlfn.XLOOKUP(D313,SKU_Master!A:A,SKU_Master!B:B,"Not on master")} -> 0 | F313: {=_xlfn.XLOOKUP(C313,Account_Master!A:A,Account_Master!B:B,"Not on master")} -> 0 | G313: {=_xlfn.XLOOKUP(C313,Account_Master!A:A,Account_Master!C:C,"Not on master")} -> 0 | H313: 4.5 | I313: 4.5 | J313: =I313-H313 -> 0 | K313: =IF(H313=0,"",J313/H313) -> 0 | L313: =IF(OR(AND(H313=0,ABS(J313)>=0.01),AND(H313<>0,ABS(K313)>VarianceThreshold)),"Review","OK") -> 0
A314: D01 | B314: 2023-11-27 | C314: 2648 | D314: 28081 | E314: {=_xlfn.XLOOKUP(D314,SKU_Master!A:A,SKU_Master!B:B,"Not on master")} -> 0 | F314: {=_xlfn.XLOOKUP(C314,Account_Master!A:A,Account_Master!B:B,"Not on master")} -> 0 | G314: {=_xlfn.XLOOKUP(C314,Account_Master!A:A,Account_Master!C:C,"Not on master")} -> 0 | H314: 0.7 | I314: 0.7 | J314: =I314-H314 -> 0 | K314: =IF(H314=0,"",J314/H314) -> 0 | L314: =IF(OR(AND(H314=0,ABS(J314)>=0.01),AND(H314<>0,ABS(K314)>VarianceThreshold)),"Review","OK") -> 0
A315: D01 | B315: 2023-11-27 | C315: 6199 | D315: 32462 | E315: {=_xlfn.XLOOKUP(D315,SKU_Master!A:A,SKU_Master!B:B,"Not on master")} -> 0 | F315: {=_xlfn.XLOOKUP(C315,Account_Master!A:A,Account_Master!B:B,"Not on master")} -> 0 | G315: {=_xlfn.XLOOKUP(C315,Account_Master!A:A,Account_Master!C:C,"Not on master")} -> 0 | H315: 0.75 | I315: 0.75 | J315: =I315-H315 -> 0 | K315: =IF(H315=0,"",J315/H315) -> 0 | L315: =IF(OR(AND(H315=0,ABS(J315)>=0.01),AND(H315<>0,ABS(K315)>VarianceThreshold)),"Review","OK") -> 0
A316: D01 | B316: 2023-11-27 | C316: 6245 | D316: 33663 | E316: {=_xlfn.XLOOKUP(D316,SKU_Master!A:A,SKU_Master!B:B,"Not on master")} -> 0 | F316: {=_xlfn.XLOOKUP(C316,Account_Master!A:A,Account_Master!B:B,"Not on master")} -> 0 | G316: {=_xlfn.XLOOKUP(C316,Account_Master!A:A,Account_Master!C:C,"Not on master")} -> 0 | H316: 12.75 | I316: 12.75 | J316: =I316-H316 -> 0 | K316: =IF(H316=0,"",J316/H316) -> 0 | L316: =IF(OR(AND(H316=0,ABS(J316)>=0.01),AND(H316<>0,ABS(K316)>VarianceThreshold)),"Review","OK") -> 0
... A817: D02 | B817: 2023-04-03 | C817: 6236 | D817: 920374 | E817: {=_xlfn.XLOOKUP(D817,SKU_Master!A:A,SKU_Master!B:B,"Not on master")} -> 0 | F817: {=_xlfn.XLOOKUP(C817,Account_Master!A:A,Account_Master!B:B,"Not on master")} -> 0 | G817: {=_xlfn.XLOOKUP(C817,Account_Master!A:A,Account_Master!C:C,"Not on master")} -> 0 | H817: 2.25 | I817: 2.25 | J817: =I817-H817 -> 0 | K817: =IF(H817=0,"",J817/H817) -> 0 | L817: =IF(OR(AND(H817=0,ABS(J817)>=0.01),AND(H817<>0,ABS(K817)>VarianceThreshold)),"Review","OK") -> 0
A818: D02 | B818: 2023-04-10 | C818: 5207 | D818: 100686 | E818: {=_xlfn.XLOOKUP(D818,SKU_Master!A:A,SKU_Master!B:B,"Not on master")} -> 0 | F818: {=_xlfn.XLOOKUP(C818,Account_Master!A:A,Account_Master!B:B,"Not on master")} -> 0 | G818: {=_xlfn.XLOOKUP(C818,Account_Master!A:A,Account_Master!C:C,"Not on master")} -> 0 | H818: 1.2 | I818: 0 | J818: =I818-H818 -> 0 | K818: =IF(H818=0,"",J818/H818) -> 0 | L818: =IF(OR(AND(H818=0,ABS(J818)>=0.01),AND(H818<>0,ABS(K818)>VarianceThreshold)),"Review","OK") -> 0 | M818: Missing Week
A819: D02 | B819: 2023-04-10 | C819: 2509 | D819: 14519 | E819: {=_xlfn.XLOOKUP(D819,SKU_Master!A:A,SKU_Master!B:B,"Not on master")} -> 0 | F819: {=_xlfn.XLOOKUP(C819,Account_Master!A:A,Account_Master!B:B,"Not on master")} -> 0 | G819: {=_xlfn.XLOOKUP(C819,Account_Master!A:A,Account_Master!C:C,"Not on master")} -> 0 | H819: 9 | I819: 0 | J819: =I819-H819 -> 0 | K819: =IF(H819=0,"",J819/H819) -> 0 | L819: =IF(OR(AND(H819=0,ABS(J819)>=0.01),AND(H819<>0,ABS(K819)>VarianceThreshold)),"Review","OK") -> 0 | M819: Missing Week
A820: D02 | B820: 2023-04-10 | C820: 010168 | D820: 16519 | E820: {=_xlfn.XLOOKUP(D820,SKU_Master!A:A,SKU_Master!B:B,"Not on master")} -> 0 | F820: {=_xlfn.XLOOKUP(C820,Account_Master!A:A,Account_Master!B:B,"Not on master")} -> 0 | G820: {=_xlfn.XLOOKUP(C820,Account_Master!A:A,Account_Master!C:C,"Not on master")} -> 0 | H820: 0.4 | I820: 0 | J820: =I820-H820 -> 0 | K820: =IF(H820=0,"",J820/H820) -> 0 | L820: =IF(OR(AND(H820=0,ABS(J820)>=0.01),AND(H820<>0,ABS(K820)>VarianceThreshold)),"Review","OK") -> 0 | M820: Missing Week
A821: D02 | B821: 2023-04-10 | C821: 3773 | D821: 19477 | E821: {=_xlfn.XLOOKUP(D821,SKU_Master!A:A,SKU_Master!B:B,"Not on master")} -> 0 | F821: {=_xlfn.XLOOKUP(C821,Account_Master!A:A,Account_Master!B:B,"Not on master")} -> 0 | G821: {=_xlfn.XLOOKUP(C821,Account_Master!A:A,Account_Master!C:C,"Not on master")} -> 0 | H821: 26 | I821: 0 | J821: =I821-H821 -> 0 | K821: =IF(H821=0,"",J821/H821) -> 0 | L821: =IF(OR(AND(H821=0,ABS(J821)>=0.01),AND(H821<>0,ABS(K821)>VarianceThreshold)),"Review","OK") -> 0 | M821: Missing Week
A822: D02 | B822: 2023-04-10 | C822: 3773 | D822: 27920 | E822: {=_xlfn.XLOOKUP(D822,SKU_Master!A:A,SKU_Master!B:B,"Not on master")} -> 0 | F822: {=_xlfn.XLOOKUP(C822,Account_Master!A:A,Account_Master!B:B,"Not on master")} -> 0 | G822: {=_xlfn.XLOOKUP(C822,Account_Master!A:A,Account_Master!C:C,"Not on master")} -> 0 | H822: 9 | I822: 0 | J822: =I822-H822 -> 0 | K822: =IF(H822=0,"",J822/H822) -> 0 | L822: =IF(OR(AND(H822=0,ABS(J822)>=0.01),AND(H822<>0,ABS(K822)>VarianceThreshold)),"Review","OK") -> 0 | M822: Missing Week
A823: D02 | B823: 2023-04-10 | C823: 2661 | D823: 37500 | E823: {=_xlfn.XLOOKUP(D823,SKU_Master!A:A,SKU_Master!B:B,"Not on master")} -> 0 | F823: {=_xlfn.XLOOKUP(C823,Account_Master!A:A,Account_Master!B:B,"Not on master")} -> 0 | G823: {=_xlfn.XLOOKUP(C823,Account_Master!A:A,Account_Master!C:C,"Not on master")} -> 0 | H823: 0.4 | I823: 0 | J823: =I823-H823 -> 0 | K823: =IF(H823=0,"",J823/H823) -> 0 | L823: =IF(OR(AND(H823=0,ABS(J823)>=0.01),AND(H823<>0,ABS(K823)>VarianceThreshold)),"Review","OK") -> 0 | M823: Missing Week
A824: D02 | B824: 2023-04-10 | C824: 4492 | D824: 43121 | E824: {=_xlfn.XLOOKUP(D824,SKU_Master!A:A,SKU_Master!B:B,"Not on master")} -> 0 | F824: {=_xlfn.XLOOKUP(C824,Account_Master!A:A,Account_Master!B:B,"Not on master")} -> 0 | G824: {=_xlfn.XLOOKUP(C824,Account_Master!A:A,Account_Master!C:C,"Not on master")} -> 0 | H824: 2 | I824: 0 | J824: =I824-H824 -> 0 | K824: =IF(H824=0,"",J824/H824) -> 0 | L824: =IF(OR(AND(H824=0,ABS(J824)>=0.01),AND(H824<>0,ABS(K824)>VarianceThreshold)),"Review","OK") -> 0 | M824: Missing Week
A825: D02 | B825: 2023-04-10 | C825: 2590 | D825: 58913 | E825: {=_xlfn.XLOOKUP(D825,SKU_Master!A:A,SKU_Master!B:B,"Not on master")} -> 0 | F825: {=_xlfn.XLOOKUP(C825,Account_Master!A:A,Account_Master!B:B,"Not on master")} -> 0 | G825: {=_xlfn.XLOOKUP(C825,Account_Master!A:A,Account_Master!C:C,"Not on master")} -> 0 | H825: 84 | I825: 0 | J825: =I825-H825 -> 0 | K825: =IF(H825=0,"",J825/H825) -> 0 | L825: =IF(OR(AND(H825=0,ABS(J825)>=0.01),AND(H825<>0,ABS(K825)>VarianceThreshold)),"Review","OK") -> 0 | M825: Missing Week
A826: D02 | B826: 2023-04-10 | C826: 010077 | D826: 64866 | E826: {=_xlfn.XLOOKUP(D826,SKU_Master!A:A,SKU_Master!B:B,"Not on master")} -> 0 | F826: {=_xlfn.XLOOKUP(C826,Account_Master!A:A,Account_Master!B:B,"Not on master")} -> 0 | G826: {=_xlfn.XLOOKUP(C826,Account_Master!A:A,Account_Master!C:C,"Not on master")} -> 0 | H826: 143.25 | I826: 0 | J826: =I826-H826 -> 0 | K826: =IF(H826=0,"",J826/H826) -> 0 | L826: =IF(OR(AND(H826=0,ABS(J826)>=0.01),AND(H826<>0,ABS(K826)>VarianceThreshold)),"Review","OK") -> 0 | M826: Missing Week
A827: D02 | B827: 2023-04-10 | C827: 6173 | D827: 64904 | E827: {=_xlfn.XLOOKUP(D827,SKU_Master!A:A,SKU_Master!B:B,"Not on master")} -> 0 | F827: {=_xlfn.XLOOKUP(C827,Account_Master!A:A,Account_Master!B:B,"Not on master")} -> 0 | G827: {=_xlfn.XLOOKUP(C827,Account_Master!A:A,Account_Master!C:C,"Not on master")} -> 0 | H827: 287 | I827: 0 | J827: =I827-H827 -> 0 | K827: =IF(H827=0,"",J827/H827) -> 0 | L827: =IF(OR(AND(H827=0,ABS(J827)>=0.01),AND(H827<>0,ABS(K827)>VarianceThreshold)),"Review","OK") -> 0 | M827: Missing Week
A828: D02 | B828: 2023-04-10 | C828: 5618 | D828: 65013 | E828: {=_xlfn.XLOOKUP(D828,SKU_Master!A:A,SKU_Master!B:B,"Not on master")} -> 0 | F828: {=_xlfn.XLOOKUP(C828,Account_Master!A:A,Account_Master!B:B,"Not on master")} -> 0 | G828: {=_xlfn.XLOOKUP(C828,Account_Master!A:A,Account_Master!C:C,"Not on master")} -> 0 | H828: 64.95 | I828: 0 | J828: =I828-H828 -> 0 | K828: =IF(H828=0,"",J828/H828) -> 0 | L828: =IF(OR(AND(H828=0,ABS(J828)>=0.01),AND(H828<>0,ABS(K828)>VarianceThreshold)),"Review","OK") -> 0 | M828: Missing Week
A829: D02 | B829: 2023-04-10 | C829: 2605 | D829: 67180 | E829: {=_xlfn.XLOOKUP(D829,SKU_Master!A:A,SKU_Master!B:B,"Not on master")} -> 0 | F829: {=_xlfn.XLOOKUP(C829,Account_Master!A:A,Account_Master!B:B,"Not on master")} -> 0 | G829: {=_xlfn.XLOOKUP(C829,Account_Master!A:A,Account_Master!C:C,"Not on master")} -> 0 | H829: 3.6 | I829: 0 | J829: =I829-H829 -> 0 | K829: =IF(H829=0,"",J829/H829) -> 0 | L829: =IF(OR(AND(H829=0,ABS(J829)>=0.01),AND(H829<>0,ABS(K829)>VarianceThreshold)),"Review","OK") -> 0 | M829: Missing Week
...

Sheet Pivot_Ready
A1: distributor_id | B1: week | C1: internal_liters | D1: feed_liters | E1: variance_liters | F1: variance_pct
A2: D01 | B2: 2023-01-02 | C2: 81668.09 | D2: 81686.09 | E2: =D2-C2 -> 0 | F2: =IF(C2=0,"",E2/C2) -> 0
A3: D01 | B3: 2023-01-09 | C3: 90398.39 | D3: 90414.59 | E3: =D3-C3 -> 0 | F3: =IF(C3=0,"",E3/C3) -> 0
A4: D01 | B4: 2023-01-16 | C4: 83173.23 | D4: 83174.78 | E4: =D4-C4 -> 0 | F4: =IF(C4=0,"",E4/C4) -> 0
A5: D01 | B5: 2023-01-23 | C5: 86031.79 | D5: 86032.59 | E5: =D5-C5 -> 0 | F5: =IF(C5=0,"",E5/C5) -> 0
A6: D01 | B6: 2023-01-30 | C6: 87402.99 | D6: 87412.46 | E6: =D6-C6 -> 0 | F6: =IF(C6=0,"",E6/C6) -> 0
A7: D01 | B7: 2023-02-06 | C7: 116111.4 | D7: 116111.4 | E7: =D7-C7 -> 0 | F7: =IF(C7=0,"",E7/C7) -> 0
A8: D01 | B8: 2023-02-13 | C8: 85431.26 | D8: 85437.76 | E8: =D8-C8 -> 0 | F8: =IF(C8=0,"",E8/C8) -> 0
A9: D01 | B9: 2023-02-20 | C9: 94040.56 | D9: 94050.51 | E9: =D9-C9 -> 0 | F9: =IF(C9=0,"",E9/C9) -> 0
A10: D01 | B10: 2023-02-27 | C10: 94574.52 | D10: 94574.52 | E10: =D10-C10 -> 0 | F10: =IF(C10=0,"",E10/C10) -> 0
A11: D01 | B11: 2023-03-06 | C11: 113708.63 | D11: 113721.03 | E11: =D11-C11 -> 0 | F11: =IF(C11=0,"",E11/C11) -> 0
A12: D01 | B12: 2023-03-13 | C12: 81697.73 | D12: 81697.73 | E12: =D12-C12 -> 0 | F12: =IF(C12=0,"",E12/C12) -> 0
A13: D01 | B13: 2023-03-20 | C13: 88319.85 | D13: 88336.35 | E13: =D13-C13 -> 0 | F13: =IF(C13=0,"",E13/C13) -> 0
... A841: D08 | B841: 2024-12-30 | C841: 13927.04 | D841: 13936.74 | E841: =D841-C841 -> 0 | F841: =IF(C841=0,"",E841/C841) -> 0

Sheet Top_Discrepancies
A1: distributor_id | B1: sku_id | C1: week | D1: internal_volume | E1: feed_volume | F1: variance | G1: variance_pct | H1: flagged | I1: root_cause
A2: D05 | B2: 1799 | C2: 2024-11-04 | D2: 11564 | E2: 0 | F2: -11564 | G2: -1 | H2: 1 | I2: Missing Week
A3: D02 | B3: 11788 | C3: 2023-05-01 | D3: 4434.5 | E3: 0 | F3: -4434.5 | G3: -1 | H3: 1 | I3: Missing Week
A4: D02 | B4: 38178 | C4: 2023-05-01 | D4: 4308.5 | E4: 0 | F4: -4308.5 | G4: -1 | H4: 1 | I4: Missing Week
A5: D05 | B5: 11788 | C5: 2024-10-21 | D5: 4161.5 | E5: 0 | F5: -4161.5 | G5: -1 | H5: 1 | I5: Missing Week
A6: D05 | B6: 11788 | C6: 2024-10-28 | D6: 4060 | E6: 0 | F6: -4060 | G6: -1 | H6: 1 | I6: Missing Week
A7: D08 | B7: 936600 | C7: 2024-10-14 | D7: 3150 | E7: 0 | F7: -3150 | G7: -1 | H7: 1 | I7: Unmapped Code
A8: D08 | B8: ZZ0009678 | C8: 2024-10-14 | D8: 0 | E8: 3150 | F8: 3150 | H8: 1 | I8: Unmapped Code
A9: D05 | B9: 38008 | C9: 2024-11-04 | D9: 2919 | E9: 0 | F9: -2919 | G9: -1 | H9: 1 | I9: Missing Week
A10: D05 | B10: 34368 | C10: 2024-11-04 | D10: 2866.5 | E10: 0 | F10: -2866.5 | G10: -1 | H10: 1 | I10: Missing Week
A11: D05 | B11: 102285 | C11: 2024-11-04 | D11: 2758 | E11: 0 | F11: -2758 | G11: -1 | H11: 1 | I11: Missing Week
A12: D03 | B12: 936600 | C12: 2023-10-09 | D12: 2520 | E12: 0 | F12: -2520 | G12: -1 | H12: 1 | I12: Unit/Format Issue
A13: D05 | B13: 1799 | C13: 2024-10-28 | D13: 2341.5 | E13: 0 | F13: -2341.5 | G13: -1 | H13: 1 | I13: Missing Week
A14: D02 | B14: 11788 | C14: 2023-04-24 | D14: 2297.75 | E14: 0 | F14: -2297.75 | G14: -1 | H14: 1 | I14: Missing Week
A15: D02 | B15: 11788 | C15: 2023-05-08 | D15: 2254 | E15: 0 | F15: -2254 | G15: -1 | H15: 1 | I15: Missing Week
A16: D02 | B16: 58838 | C16: 2023-04-10 | D16: 2229.5 | E16: 0 | F16: -2229.5 | G16: -1 | H16: 1 | I16: Missing Week
A17: D02 | B17: 936859 | C17: 2023-04-24 | D17: 2016 | E17: 0 | F17: -2016 | G17: -1 | H17: 1 | I17: Missing Week
A18: D03 | B18: 936600 | C18: 2023-12-25 | D18: 1890 | E18: 0 | F18: -1890 | G18: -1 | H18: 1 | I18: Unit/Format Issue
A19: D08 | B19: 962094 | C19: 2023-05-01 | D19: 1890 | E19: 0 | F19: -1890 | G19: -1 | H19: 1 | I19: Unmapped Code
A20: D08 | B20: ZZ0010379 | C20: 2023-05-01 | D20: 0 | E20: 1890 | F20: 1890 | H20: 1 | I20: Unmapped Code
A21: D02 | B21: 75087 | C21: 2023-05-01 | D21: 1812 | E21: 0 | F21: -1812 | G21: -1 | H21: 1 | I21: Missing Week
A22: D05 | B22: 36308 | C22: 2024-10-28 | D22: 1799 | E22: 0 | F22: -1799 | G22: -1 | H22: 1 | I22: Missing Week
A23: D07 | B23: 1799 | C23: 2023-03-27 | D23: 4515 | E23: 2940 | F23: -1575 | G23: -0.348837 | H23: 1 | I23: Unmapped Code
A24: D07 | B24: ZZ0018352 | C24: 2023-03-27 | D24: 0 | E24: 1575 | F24: 1575 | H24: 1 | I24: Unmapped Code
A25: D05 | B25: 77487 | C25: 2024-11-04 | D25: 1536 | E25: 0 | F25: -1536 | G25: -1 | H25: 1 | I25: Missing Week
A26: D02 | B26: 11788 | C26: 2023-04-17 | D26: 1485.75 | E26: 0 | F26: -1485.75 | G26: -1 | H26: 1 | I26: Missing Week

Sheet SKU_Master
A1: sku_id | B1: description | C1: category | D1: category_name | E1: pack | F1: bottle_ml | G1: vendor
A2: 100026 | B2: ABSOLUT W/FEVER TREE GINGER BEER | C2: 1701100 | D2: TEMPORARY & SPECIALTY PACKAGES | E2: 6 | F2: 750 | G2: PERNOD RICARD USA
A3: 10006 | B3: SCORESBY RARE SCOTCH | C3: 1012200 | D3: SCOTCH WHISKIES | E3: 12 | F3: 750 | G3: SAZERAC COMPANY INC
A4: 100077 | B4: KRAKEN RUM W/TIKI GLASS | C4: 1701100 | D4: TEMPORARY & SPECIALTY PACKAGES | E4: 6 | F4: 750 | G4: PROXIMO
A5: 10008 | B5: SCORESBY RARE SCOTCH | C5: 1012200 | D5: SCOTCH WHISKIES | E5: 6 | F5: 1750 | G5: SAZERAC COMPANY INC
A6: 10009 | B6: SCORESBY RARE SCOTCH | C6: 1012200 | D6: SCOTCH WHISKIES | E6: 12 | F6: 1000 | G6: SAZERAC COMPANY INC
A7: 100104 | B7: HERRADURA ULTRA ANEJO | C7: 1022200 | D7: 100% AGAVE TEQUILA | E7: 6 | F7: 750 | G7: BROWN FORMAN CORP.
A8: 100148 | B8: JACK DANIELS SINGLE BARREL W/SNIFTER GLASS | C8: 1701100 | D8: TEMPORARY & SPECIALTY PACKAGES | E8: 6 | F8: 750 | G8: BROWN FORMAN CORP.
A9: 100215 | B9: TEQUILA ROSE LIQUEUR W/2 SHOT GLASSES | C9: 1701100 | D9: TEMPORARY & SPECIALTY PACKAGES | E9: 6 | F9: 750 | G9: MCCORMICK DISTILLING CO.
A10: 100220 | B10: TWISTED SHOTZ TRADITIONAL PARTY PACK 3.0 | C10: 1071000 | D10: COCKTAILS/RTD | E10: 1 | F10: 2250 | G10: MHW LTD
A11: 100245 | B11: BOMBAY SAPPHIRE GIFT TIN | C11: 1701100 | D11: TEMPORARY & SPECIALTY PACKAGES | E11: 6 | F11: 750 | G11: BACARDI USA INC
A12: 100306 | B12: PATRON EXTRA ANEJO | C12: 1022200 | D12: 100% AGAVE TEQUILA | E12: 6 | F12: 750 | G12: BACARDI USA INC
A13: 100413 | B13: FIREBALL CINNAMON WHISKEY PARTY BUCKET | C13: 1081600 | D13: WHISKEY LIQUEUR | E13: 1 | F13: 50 | G13: SAZERAC COMPANY INC
... A6562: 999996 | B6562: VIKRE BOREAL SPRUCE GIN | C6562: 1041100 | D6562: AMERICAN DRY GINS | E6562: 6 | F6562: 750 | G6562: VIKRE DISTILLERY

Sheet Account_Master
A1: account_id | B1: name | C1: city | D1: county | E1: territory_id
A2: 010003 | B2: TOP SHELF LIQUOR / IOWA CITY | C2: IOWA CITY | D2: JOHNSON | E2: T052
A3: 010004 | B3: JACK & JILL STORE / WEST BRANCH | C3: WEST BRANCH | D3: CEDAR | E3: T016
A4: 010005 | B4: THE CROWN LIQUOR / IOWA CITY | C4: IOWA CITY | D4: JOHNSON | E4: T052
A5: 010016 | B5: KWIK STAR #1180 / PERRY | C5: PERRY | D5: DALLAS | E5: T025
A6: 010017 | B6: KWIK STAR #1119 / EMMETSBURG | C6: EMMETSBURG | D6: PALO ALTO | E6: T074
A7: 010018 | B7: KWIK STAR #710 / TOLEDO | C7: TOLEDO | D7: TAMA | E7: T086
A8: 010019 | B8: OELWEIN MART / OELWEIN | C8: OELWEIN | D8: FAYETTE | E8: T033
A9: 010020 | B9: LOCAL LIQUOR / PANORA | C9: PANORA | D9: GUTHRIE | E9: T039
A10: 010021 | B10: WORLD CLASS LIQUOR AND TOBACCO / BONDURANT | C10: BONDURANT | D10: POLK | E10: T077
A11: 010023 | B11: HY-VEE FAST AND FRESH #3 (7592) / WEST DES MOINES | C11: WEST DES MOINES | D11: POLK | E11: T077
A12: 010024 | B12: HY-VEE FAST AND FRESH #2 (7591) / WEST DES MOINES | C12: WEST DES MOINES | D12: POLK | E12: T077
... A2274: 9911 | B2274: SOUTHERN GLAZERS WINE & SPIRITS OF IOWA | C2274: GRIMES | D2274: POLK | E2274: T077

Sheet README
A1: How to compare the two datasets
A3: This workbook compares two views of the same sales. Internal liters come from the Iowa liquor sales book, rolled up by week. Feed liters come from the distributor files after duplicate rows are removed, item codes are mapped, and negative volumes are dropped.
A5: 1. Start on Summary. The yellow cell is a distributor dropdown. Pick D01 through D08.
A6: 2. Internal liters, feed liters, and variance percent update with SUMIFS formulas. You do not need to copy values.
A7: 3. A variance percent beyond the flag threshold (5%) is large enough to review. The All distributors block shows every distributor with the same formulas.
A8: 4. Open Top_Discrepancies for the 25 largest liter gaps. Red means the absolute variance is over 10%. Amber means it is from 5% to 10%.
A9: 5. Weekly_Compare is a 5,000 row sample, not the full book. sku_name, account_name, and city are XLOOKUP formulas against SKU_Master and Account_Master. Not on master means the code is missing from the internal list. compare_flag says Review when the sample line crosses the threshold.
A10: 6. The account on Weekly_Compare is the store with the most internal liters for that distributor, week, and SKU. Feed liters on that row are the distributor total for the SKU and week, not that store alone.
A11: 7. Pivot_Ready is an Excel table with one row per distributor and week. Use Insert, PivotTable if you want a different cut. Summary reads this table.
A12: 8. Do not type over formula cells. Filter and sort are safe.
